Workbook
Name ActualNumberOfPayments: IFERROR(IF([0]!LoanIsGood,IF([0]!PaymentsPerYear=1,1,MATCH(0.01,Copy1!End_Bal,-1)+1)),"")
Name ActualNumberOfPayments: IFERROR(IF([0]!LoanIsGood,IF([0]!PaymentsPerYear=1,1,MATCH(0.01,FV_April25!End_Bal,-1)+1)),"")
Name ActualNumberOfPayments: IFERROR(IF([0]!LoanIsGood,IF([0]!PaymentsPerYear=1,1,MATCH(0.01,FV_August25!End_Bal,-1)+1)),"")
Name ActualNumberOfPayments: IFERROR(IF([0]!LoanIsGood,IF([0]!PaymentsPerYear=1,1,MATCH(0.01,FV_Dec25!End_Bal,-1)+1)),"")
Name ActualNumberOfPayments: IFERROR(IF([0]!LoanIsGood,IF([0]!PaymentsPerYear=1,1,MATCH(0.01,FV_Feb26!End_Bal,-1)+1)),"")
Name ActualNumberOfPayments: IFERROR(IF([0]!LoanIsGood,IF([0]!PaymentsPerYear=1,1,MATCH(0.01,FV_Jan26!End_Bal,-1)+1)),"")
Name ActualNumberOfPayments: IFERROR(IF([0]!LoanIsGood,IF([0]!PaymentsPerYear=1,1,MATCH(0.01,'FV_July25 '!End_Bal,-1)+1)),"")
Name ActualNumberOfPayments: IFERROR(IF([0]!LoanIsGood,IF([0]!PaymentsPerYear=1,1,MATCH(0.01,FV_July25TEST!End_Bal,-1)+1)),"")
Name ActualNumberOfPayments: IFERROR(IF([0]!LoanIsGood,IF([0]!PaymentsPerYear=1,1,MATCH(0.01,FV_June25!End_Bal,-1)+1)),"")
Name ActualNumberOfPayments: IFERROR(IF([0]!LoanIsGood,IF([0]!PaymentsPerYear=1,1,MATCH(0.01,FV_Mar26!End_Bal,-1)+1)),"")
Name ActualNumberOfPayments: IFERROR(IF([0]!LoanIsGood,IF([0]!PaymentsPerYear=1,1,MATCH(0.01,FV_May25!End_Bal,-1)+1)),"")
Name ActualNumberOfPayments: IFERROR(IF([0]!LoanIsGood,IF([0]!PaymentsPerYear=1,1,MATCH(0.01,FV_Nov25!End_Bal,-1)+1)),"")
Name ActualNumberOfPayments: IFERROR(IF([0]!LoanIsGood,IF([0]!PaymentsPerYear=1,1,MATCH(0.01,FV_October25!End_Bal,-1)+1)),"")
Name ActualNumberOfPayments: IFERROR(IF([0]!LoanIsGood,IF([0]!PaymentsPerYear=1,1,MATCH(0.01,FV_PLANNING!End_Bal,-1)+1)),"")
Name ActualNumberOfPayments: IFERROR(IF([0]!LoanIsGood,IF([0]!PaymentsPerYear=1,1,MATCH(0.01,FV_PLANNING2!End_Bal,-1)+1)),"")
Name ActualNumberOfPayments: IFERROR(IF([0]!LoanIsGood,IF([0]!PaymentsPerYear=1,1,MATCH(0.01,FV_Play!End_Bal,-1)+1)),"")
Name ActualNumberOfPayments: IFERROR(IF([0]!LoanIsGood,IF([0]!PaymentsPerYear=1,1,MATCH(0.01,FV_September25!End_Bal,-1)+1)),"")
Name ActualNumberOfPayments: IFERROR(IF([0]!LoanIsGood,IF([0]!PaymentsPerYear=1,1,MATCH(0.01,HouseView!End_Bal,-1)+1)),"")
Name ActualNumberOfPayments: IFERROR(IF(LoanIsGood,IF(PaymentsPerYear=1,1,MATCH(0.01,End_Bal,-1)+1)),"")
Name ActualNumberOfPayments: IFERROR(IF([0]!LoanIsGood,IF([0]!PaymentsPerYear=1,1,MATCH(0.01,Newhouse!End_Bal,-1)+1)),"")
Name ActualNumberOfPayments: IFERROR(IF([0]!LoanIsGood,IF([0]!PaymentsPerYear=1,1,MATCH(0.01,PayAsh!End_Bal,-1)+1)),"")
Name ActualNumberOfPayments: IFERROR(IF([0]!LoanIsGood,IF([0]!PaymentsPerYear=1,1,MATCH(0.01,[0]!End_Bal,-1)+1)),"")
Name ActualNumberOfPayments: IFERROR(IF([0]!LoanIsGood,IF([0]!PaymentsPerYear=1,1,MATCH(0.01,T!End_Bal,-1)+1)),"")
Name ActualNumberOfPayments: IFERROR(IF([0]!LoanIsGood,IF([0]!PaymentsPerYear=1,1,MATCH(0.01,'T2'!End_Bal,-1)+1)),"")
Name ActualNumberOfPayments: IFERROR(IF(LoanIsGood,IF(PaymentsPerYear=1,1,MATCH(0.01,End_Bal,-1)+1)),"")
Name ColumnTitle1: #REF!
Name ColumnTitle1: #REF!
Name ColumnTitle1: #REF!
Name ColumnTitle1: #REF!
Name ColumnTitle1: #REF!
Name ColumnTitle1: #REF!
Name ColumnTitle1: #REF!
Name ColumnTitle1: #REF!
Name ColumnTitle1: #REF!
Name ColumnTitle1: #REF!
Name ColumnTitle1: #REF!
Name ColumnTitle1: #REF!
Name ColumnTitle1: #REF!
Name ColumnTitle1: #REF!
Name ColumnTitle1: #REF!
Name ColumnTitle1: #REF!
Name ColumnTitle1: #REF!
Name ColumnTitle1: #REF!
Name ColumnTitle1: #REF!
Name ColumnTitle1: #REF!
Name ColumnTitle1: #REF!
Name ColumnTitle1: #REF!
Name ColumnTitle1: #REF!
Name End_Bal: #REF!
Name End_Bal: #REF!
Name End_Bal: #REF!
Name End_Bal: #REF!
Name End_Bal: #REF!
Name End_Bal: #REF!
Name End_Bal: #REF!
Name End_Bal: #REF!
Name End_Bal: #REF!
Name End_Bal: #REF!
Name End_Bal: #REF!
Name End_Bal: #REF!

Sheet Monthly Expenses Budget
B1: MONTHLY BUDGET TRACKER | P1: MONTHLY BUDGET TRACKER
C3: Monthly Target / Budget | E3: ACTUALS - 2024 | P3: ACTUALS - 2025
E4: 45292 | F4: 45323 | G4: 45352 | H4: 45383 | I4: 45413 | J4: 45444 | K4: 45474 | L4: 45505 | M4: 45536 | N4: 45566 | O4: 45597 | P4: 45627 | Q4: 45658 | R4: 45689 | S4: 45717 | T4: 45748 | U4: 45778 | V4: 45809 | W4: 45839 | X4: 45870 | Y4: 45901 | Z4: 45931 | AA4: 45962 | AB4: 45992
B5: Home and other Fixed Expenses | C5: =SUM(C6:C10) -> 0 | E5: =SUM(E6:E10) -> 0 | F5: =SUM(F6:F10) -> 0 | G5: =SUM(G6:G10) -> 0 | H5: =SUM(H6:H10) -> 0 | I5: =SUM(I6:I10) -> 0 | J5: =SUM(J6:J10) -> 0 | K5: =SUM(K6:K10) -> 0 | L5: =SUM(L6:L10) -> 0 | ... AB5: =SUM(AB6:AB10) -> 0
B6: Home Loan / Mortgage | E6: =$C$5 -> 0 | F6: =$C$5 -> 0 | G6: =$C$5 -> 0 | H6: =$C$5 -> 0 | I6: =$C$5 -> 0 | J6: =$C$5 -> 0 | K6: =$C$5 -> 0 | L6: =$C$5 -> 0 | ... AB6: =$C$5 -> 0
B7: Personal Loans
B8: Credit Card Repayments
B9: Car Lease
B10: Rent (cost per month)
B12: Essentials | C12: =SUM(C13:C20) -> 875.7325 | E12: =SUM(E13:E20) -> 957.21583 | F12: =SUM(F13:F20) -> 957.21583 | G12: =SUM(G13:G20) -> 937.80583 | H12: =SUM(H13:H20) -> 842.98917 | I12: =SUM(I13:I20) -> 943.55583 | J12: =SUM(J13:J20) -> 943.55583 | K12: =SUM(K13:K20) -> 1010.7658 | L12: =SUM(L13:L20) -> 893.19917 | ... AB12: =SUM(AB13:AB20) -> 875.7325
B13: Electricity | C13: 116.66667 | E13: 198.15 | F13: 198.15 | G13: 198.15 | H13: 116.66667 | I13: 217.23333 | J13: 217.23333 | K13: 217.23333 | L13: 99.666667 | M13: 99.666667 | N13: 99.666667 | O13: 274.33333 | P13: 274.33333 | Q13: 274.33333 | R13: 116.66667 | S13: 116.66667 | T13: 116.66667 | U13: 116.66667 | V13: 116.66667 | W13: 116.66667 | X13: 116.66667 | Y13: 116.66667 | Z13: 116.66667 | AA13: 116.66667 | AB13: 116.66667
B14: Gas | C14: 41.666667 | E14: 41.666667 | F14: 41.666667 | G14: 41.666667 | H14: 41.666667 | I14: 41.666667 | J14: 41.666667 | K14: 41.666667 | L14: 41.666667 | M14: 41.666667 | N14: 41.666667 | O14: 41.666667 | P14: 41.666667 | Q14: 41.666667 | R14: 41.666667 | S14: 41.666667 | T14: 41.666667 | U14: 41.666667 | V14: 41.666667 | W14: 41.666667 | X14: 41.666667 | Y14: 41.666667 | Z14: 41.666667 | AA14: 41.666667 | AB14: 41.666667
B15: Water | C15: 170 | E15: 170 | F15: 170 | G15: 150.59 | H15: 137.25667 | I15: 137.25667 | J15: 137.25667 | K15: 154.46667 | L15: 154.46667 | M15: 154.46667 | N15: 160 | O15: 160 | P15: 160 | Q15: 170 | R15: 170 | S15: 170 | T15: 170 | U15: 170 | V15: 170 | W15: 170 | X15: 170 | Y15: 170 | Z15: 170 | AA15: 170 | AB15: 170
B16: Council | C16: 172 | E16: 172 | F16: 172 | G16: 172 | H16: 172 | I16: 172 | J16: 172 | K16: 172 | L16: 172 | M16: 172 | N16: 172 | O16: 172 | P16: 172 | Q16: 172 | R16: 172 | S16: 172 | T16: 172 | U16: 172 | V16: 172 | W16: 172 | X16: 172 | Y16: 172 | Z16: 172 | AA16: 172 | AB16: 172
B17: Waterworks Insurance | C17: 375.39917 | E17: 375.39917 | F17: 375.39917 | G17: 375.39917 | H17: 375.39917 | I17: 375.39917 | J17: 375.39917 | K17: 375.39917 | L17: 375.39917 | M17: 375.39917 | N17: 375.39917 | O17: 375.39917 | P17: 375.39917 | Q17: 375.39917 | R17: 375.39917 | S17: 375.39917 | T17: 375.39917 | U17: 375.39917 | V17: 375.39917 | W17: 375.39917 | X17: 375.39917 | Y17: 375.39917 | Z17: 375.39917 | AA17: 375.39917 | AB17: 375.39917
B18: Mobile Phone TF | K18: 50 | L18: 50 | N18: 50 | O18: 65 | P18: 65 | Q18: 65 | R18: 65
B22: Groceries | C22: =SUM(C23:C29) -> 2120 | E22: =SUM(E23:E29) -> 1886.72 | F22: =SUM(F23:F29) -> 1534.94 | G22: =SUM(G23:G29) -> 2427.69 | H22: =SUM(H23:H29) -> 2999.92 | I22: =SUM(I23:I29) -> 1770.63 | J22: =SUM(J23:J29) -> 2257.22 | K22: =SUM(K23:K29) -> 2654.19 | L22: =SUM(L23:L29) -> 2156.84 | ... AB22: =SUM(AB23:AB29) -> 1400
B23: Groceries | C23: 2000 | E23: 1886.72 | F23: 1534.94 | G23: 2427.69 | H23: 2999.92 | I23: 1770.63 | J23: 1923.17 | K23: 2495.2 | L23: 2023.85 | M23: 2271.54 | N23: 2436.52 | O23: 2005.53 | P23: 2384.1 | Q23: 2991.56 | R23: 1400 | S23: 1400 | T23: 1400 | U23: 1400 | V23: 1400 | W23: 1400 | X23: 1400 | Y23: 1400 | Z23: 1400 | AA23: 1400 | AB23: 1400
B24: Nala Food | C24: 120 | J24: 334.05 | K24: 158.99 | L24: 132.99 | M24: 0 | N24: 139.99 | O24: 168.99 | P24: 43.36 | Q24: 129.6
B31: House Maintenance | C31: =SUM(C32:C37) -> 230 | E31: =SUM(E32:E37) -> 51.32 | F31: =SUM(F32:F37) -> 206.19 | G31: =SUM(G32:G37) -> 2419.71 | H31: =SUM(H32:H37) -> 4097.13 | I31: =SUM(I32:I37) -> 87.98 | J31: =SUM(J32:J37) -> 647.35 | K31: =SUM(K32:K37) -> 618.09 | L31: =SUM(L32:L37) -> 367.98 | ... AB31: =SUM(AB32:AB37) -> 30
B32: External | C32: 30 | G32: 374 | H32: 264 | I32: 87.98 | Q32: 1045 | X32: 30 | Y32: 30 | Z32: 30 | AA32: 30 | AB32: 30
B33: Maintenance general | C33: 150 | E33: 51.32 | F33: 206.19 | G33: 2045.71 | H33: 3833.13 | J33: 647.35 | K33: 618.09 | L33: 367.98 | M33: 481.48 | N33: 486.45 | O33: 363.95 | P33: 531.27 | Q33: 515.34
B34: Pool Service / Chemicals | C34: 50
B39: Health | C39: =SUM(C40:C47) -> 1514.7033 | E39: =SUM(E40:E47) -> 2527.1233 | F39: =SUM(F40:F47) -> 1030.8533 | G39: =SUM(G40:G47) -> 894.53333 | H39: =SUM(H40:H47) -> 1075.2533 | I39: =SUM(I40:I47) -> 905.12333 | J39: =SUM(J40:J47) -> 2110.2633 | K39: =SUM(K40:K47) -> 1265.8833 | L39: =SUM(L40:L47) -> 1206.9433 | ... AB39: =SUM(AB40:AB47) -> 440.83333
B40: HCF | C40: 402.75 | E40: 402.75 | F40: 402.75 | G40: 402.75 | H40: 414.12 | I40: 414.12 | J40: 414.12 | K40: 414.12 | L40: 414.12 | M40: 414.12 | N40: 414.12 | O40: 414.12 | P40: 414.12 | Q40: 414.12 | R40: 414.12
B41: Pet Insurance | C41: 183.12 | E41: 183.12 | F41: END | K41: 84.71 | L41: 56.44 | M41: 56.44 | N41: 56.44 | O41: 56.44 | P41: 56.44 | Q41: 56.44 | R41: 56.44
B42: Vet Bills/Medicine | C42: 238 | E42: 1353.69 | F42: END | J42: 263.8 | K42: 284.25 | L42: 48.2 | M42: -46.8 | N42: 112 | O42: 0 | P42: 0 | Q42: 0
B43: Medical | C43: 250 | E43: 146.73 | F43: 187.27 | G43: 50.95 | H43: 123.9 | I43: 50.17 | J43: 261.31 | K43: 41.97 | L43: 247.35 | M43: 585.33 | N43: 854.78 | O43: 580 | P43: 304.81 | Q43: 379
B44: Doctor | H44: 96.4 | J44: 730.2 | K44: 0 | L44: 0 | M44: 0 | N44: 250 | O44: 0 | P44: 0 | Q44: 0
B45: Orthodontist | C45: 440.83333 | E45: 440.83333 | F45: 440.83333 | G45: 440.83333 | H45: 440.83333 | I45: 440.83333 | J45: 440.83333 | K45: 440.83333 | L45: 440.83333 | M45: 440.83333 | N45: 440.83333 | O45: 440.83333 | P45: 440.83333 | Q45: 440.83333 | R45: 440.83333 | S45: 440.83333 | T45: 440.83333 | U45: 440.83333 | V45: 440.83333 | W45: 440.83333 | X45: 440.83333 | Y45: 440.83333 | Z45: 440.83333 | AA45: 440.83333 | AB45: 440.83333
B49: Discretionary | C49: =SUM(C50:C56) -> 1100 | E49: =SUM(E50:E56) -> 1625.98 | F49: =SUM(F50:F56) -> 2777.57 | G49: =SUM(G50:G56) -> 1438.42 | H49: =SUM(H50:H56) -> 1147.58 | I49: =SUM(I50:I56) -> 543.06 | J49: =SUM(J50:J56) -> 723.14 | K49: =SUM(K50:K56) -> 1622.83 | L49: =SUM(L50:L56) -> 808.17 | ... AB49: =SUM(AB50:AB56) -> 500
B50: Presents etc | C50: 100 | E50: 942.56 | F50: 155.93 | G50: 730.8 | H50: 435.1 | J50: 0 | K50: 506.67 | L50: 125.62 | M50: 121.96 | N50: 627.41 | O50: 1687.73 | P50: 993.87 | Q50: 24.85 | Z50: 0 | AA50: 0 | AB50: 0
B51: Entertainment | C51: 200 | E51: 99 | F51: 61.51 | G51: 95.7 | H51: 232 | I51: 79 | J51: 0 | K51: 0 | L51: 138 | M51: 0 | N51: 0 | O51: 0 | P51: 119.95 | Q51: 98 | Z51: 300 | AA51: 300 | AB51: 300
B52: Misc /Travel | C52: 200 | E52: 62.12 | F52: 129.1 | G52: 79.9 | I52: 8.85 | J52: 289.21 | K52: 573.09 | L52: 26.5 | M52: 67.27 | N52: 79.72 | O52: 1215.93 | P52: 725.48 | Q52: 221.41
B53: Eating Out | C53: 200 | E53: 264.08 | F53: 299.06 | G53: 121.8 | H53: 385.28 | I53: 371.71 | J53: 327.93 | K53: 283.31 | L53: 354.96 | M53: 740.33 | N53: 538.35 | O53: 716.76 | P53: 343.05 | Q53: 358.05
B54: Personal Care | C54: 200 | E54: 168.22 | F54: 302.81 | G54: 410.22 | H54: 95.2 | I54: 83.5 | J54: 106 | K54: 259.76 | L54: 163.09 | M54: 124 | N54: 231.34 | O54: 327.2 | P54: 207 | Q54: 303.95
B55: Wedding | C55: 200 | E55: 90 | F55: 1829.16 | Z55: 200 | AA55: 200 | AB55: 200
B58: Sports / Activities | C58: =SUM(C59:C62) -> 397.5 | E58: =SUM(E59:E62) -> 630.83333 | F58: =SUM(F59:F62) -> 630.83333 | G58: =SUM(G59:G62) -> 685.83333 | H58: =SUM(H59:H62) -> 713.31667 | I58: =SUM(I59:I62) -> 623.31667 | J58: =SUM(J59:J62) -> 600.31667 | K58: =SUM(K59:K62) -> 448.06333 | L58: =SUM(L59:L62) -> 454.73 | ... AB58: =SUM(AB59:AB62) -> 454.73
B59: Crossfit | C59: 0 | E59: 0 | F59: 0 | G59: 0 | H59: 0 | I59: 0 | J59: 0 | K59: 0 | L59: 0 | M59: 0 | N59: 0 | O59: 0 | P59: 0 | Q59: 0 | R59: 0 | S59: 0 | T59: 0 | U59: 0 | V59: 0 | W59: 0 | X59: 0
B60: Drama | C60: 147.5 | E60: 140.83333 | F60: 140.83333 | G60: 140.83333 | H60: 233.83333 | I60: 140.83333 | J60: 140.83333 | K60: 140.83333 | L60: 147.5 | M60: 147.5 | N60: 147.5 | O60: 147.5 | P60: 147.5 | Q60: 147.5 | R60: 147.5 | S60: 147.5 | T60: 147.5 | U60: 147.5 | V60: 147.5 | W60: 147.5 | X60: 147.5 | Y60: 147.5 | Z60: 147.5 | AA60: 147.5 | AB60: 147.5
...

Sheet Property Expenses
B1: Investment Expenses
B4: Forest Lake | C4: Monthly | D4: Yearly | E4: Rental Income Per week
B5: Council Rates | C5: =D5/12 -> 166.66667 | D5: 2000 | E5: 620
B6: Water Rates | C6: =D6/12 -> 83.333333 | D6: 1000
B7: Property management | C7: =D7/12 -> 236.42667 | D7: =E5*52*0.088 -> 2837.12
B8: Building/Landlords Insurance | C8: =D8/12 -> 120.83333 | D8: 1450
B10: Total | C10: =SUM(C5:C9) -> 607.26 | D10: =SUM(D5:D9) -> 7287.12
B12: Strathpine | C12: Monthly | D12: Yearly | E12: Rental Income Per week
B13: Insurance | C13: =D13/12 -> 266.66667 | D13: 3200 | E13: =39156/52 -> 753 | F13: =E13*52/12 -> 3263
B14: Council Rates | C14: =D14/12 -> 345 | D14: 4140 | F14: =F13*12 -> 39156
B15: Property management | C15: =D15/12 -> 100 | D15: 1200 | F15: 39287
B16: Repairs | C16: =D16/12 -> 125 | D16: 1500 | F16: =F15/52 -> 755.51923
B18: Total | C18: =SUM(C13:C17) -> 836.66667 | D18: =SUM(D13:D17) -> 10040
B20: Mount Sheridan | C20: Monthly | D20: Yearly | E20: Rental Income Per week
B21: Council Rates | C21: =D21/12 -> 273.66667 | D21: 3284 | E21: 730
B22: Water Rates | C22: =D22/12 -> 150 | D22: 1800
B23: Property management | C23: =D23/12 -> 278.37333 | D23: =E21*52*0.088 -> 3340.48
B24: Building/Landlords Insurance | C24: =D24/12 -> 120.83333 | D24: 1450
B26: Total | C26: =SUM(C21:C25) -> 822.87333 | D26: =SUM(D21:D25) -> 9874.48
B28: Eimeo | C28: Monthly | D28: Yearly | E28: Rental Income Per week
B29: Council Rates | C29: =D29/12 -> 273.66667 | D29: 3284 | E29: 830
B30: Water Rates | C30: =D30/12 -> 150 | D30: 1800
B31: Property management | C31: =D31/12 -> 316.50667 | D31: =E29*52*0.088 -> 3798.08
B32: Building/Landlords Insurance | C32: =D32/12 -> 120.83333 | D32: 1450
B34: Total | C34: =SUM(C29:C33) -> 861.00667 | D34: =SUM(D29:D33) -> 10332.08

Sheet FV_April25
U1: Property Growth Rate (PY) | V1: 0.07
B2: INCOME STATEMENT | L2: INPUTS!!! Fill out the ORANGE cells ONLY | U2: Stock Growth Rate (PY) | V2: 0.1
U3: Stock contribution per month | V3: 5000 | AI3: NET GROWTH FORECAST
B4: INCOME | C4: PER YEAR | D4: PER MONTH | E4: PASSIVE PM | G4: PASSIVE | H4: PER MONTH | I4: PER YEAR | L4: INCOME | U4: Yearly Prop Purchase Value | V4: 1000000
G5: PASSIVE INCOME | H5: =SUM(E8:E15) -> 2359.6 | I5: =H5*12 -> 28315.2
B6: Salary 1 | C6: =D6*12 -> 240000 | D6: =M6 -> 20000 | L6: Salary 1 (ex tax per month) | M6: 20000 | P6: Date | Q6: Date | R6: Month | S6: Properties | T6: Add Prop | U6: Stocks | V6: Savings | W6: Liabilities | X6: Add Liab | Y6: Total Net Worth
B7: Salary 2 | C7: =D7*12 -> 0 | D7: =M7 -> 0 | L7: Salary 2 (ex tax per month) | P7: 1 | Q7: =TODAY() -> 46091 | R7: =TEXT($Q7,"MMMM")&TEXT($Q7," YYYY") -> March 2026 | S7: =SUM(E44:E46) -> 3550000 | U7: =SUM(E37:E39) -> 792000 | V7: =$E$34 -> 818000 | W7: =$I$50 -> 1488000 | X7: =T7 -> 0 | Y7: =SUM(S7:V7)-W7 -> 3672000
B8: Interest Earned (from savings) | D8: =M8 -> 10 | E8: =D8 -> 10 | L8: Interest from Savings (per month) | M8: 10 | P8: 2 | Q8: =Q7+30 -> 46121 | R8: =TEXT($Q8,"MMMM")&TEXT($Q8," YYYY") -> April 2026 | S8: =($V$1/12+1)*S7+T7 -> 3570708.3 | U8: =($V$2/12+1)*U7+$V$3 -> 803600 | V8: =V7+$I$56 -> 833021.66 | W8: =W7+X7 -> 1488000 | X8: =T8 -> 0 | Y8: =SUM(S8:V8)-W8 -> 3719330
B9: Dividends | D9: =M9 -> 830 | E9: =D9 -> 830 | L9: Income from Dividends (per month) | M9: 830 | P9: 3 | Q9: =Q8+30 -> 46151 | R9: =TEXT($Q9,"MMMM")&TEXT($Q9," YYYY") -> May 2026 | S9: =($V$1/12+1)*S8+T8 -> 3591537.5 | U9: =($V$2/12+1)*U8+$V$3 -> 815296.67 | V9: =V8+$I$56 -> 848043.33 | W9: =W8+X8 -> 1488000 | X9: =T9 -> 0 | Y9: =SUM(S9:V9)-W9 -> 3766877.5
B10: Other income | D10: =M10 -> 0 | L10: Any other income (per month) | M10: 0 | P10: 4 | Q10: =Q9+30 -> 46181 | R10: =TEXT($Q10,"MMMM")&TEXT($Q10," YYYY") -> June 2026 | S10: =($V$1/12+1)*S9+T9 -> 3612488.1 | U10: =($V$2/12+1)*U9+$V$3 -> 827090.81 | V10: =V9+$I$56 -> 863064.99 | W10: =W9+X9 -> 1488000 | X10: =T10 -> 0 | Y10: =SUM(S10:V10)-W10 -> 3814643.9
P11: 5 | Q11: =Q10+30 -> 46211 | R11: =TEXT($Q11,"MMMM")&TEXT($Q11," YYYY") -> July 2026 | S11: =($V$1/12+1)*S10+T10 -> 3633560.9 | U11: =($V$2/12+1)*U10+$V$3 -> 838983.23 | V11: =V10+$I$56 -> 878086.66 | W11: =W10+X10 -> 1488000 | X11: =T11 -> 0 | Y11: =SUM(S11:V11)-W11 -> 3862630.8
B12: Real Estate / Other income: | P12: 6 | Q12: =Q11+30 -> 46241 | R12: =TEXT($Q12,"MMMM")&TEXT($Q12," YYYY") -> August 2026 | S12: =($V$1/12+1)*S11+T11 -> 3654756.7 | U12: =($V$2/12+1)*U11+$V$3 -> 850974.76 | V12: =V11+$I$56 -> 893108.32 | W12: =W11+X11 -> 1488000 | X12: =T12 -> 0 | Y12: =SUM(S12:V12)-W12 -> 3910839.8
G13: Property Yield | H13: % | P13: 7 | Q13: =Q12+30 -> 46271 | R13: =TEXT($Q13,"MMMM")&TEXT($Q13," YYYY") -> September 2026 | S13: =($V$1/12+1)*S12+T12 -> 3676076.1 | U13: =($V$2/12+1)*U12+$V$3 -> 863066.21 | V13: =V12+$I$56 -> 908129.99 | W13: =W12+X12 -> 1488000 | X13: =T13 -> 0 | Y13: =SUM(S13:V13)-W13 -> 3959272.3
B14: =L14 -> Rental income 1 (per week) | C14: =D14*12 -> 32240 | D14: =M14*52/12 -> 2686.6667 | E14: =D14-D21 -> -18.4 | G14: Investment 1 (rental income) | H14: =C14/E45 -> 0.03224 | L14: Rental income 1 (per week) | M14: 620 | P14: 8 | Q14: =Q13+30 -> 46301 | R14: =TEXT($Q14,"MMMM")&TEXT($Q14," YYYY") -> October 2026 | S14: =($V$1/12+1)*S13+T13 -> 3697519.9 | U14: =($V$2/12+1)*U13+$V$3 -> 875258.43 | V14: =V13+$I$56 -> 923151.65 | W14: =W13+X13 -> 1488000 | X14: =T14 -> 0 | Y14: =SUM(S14:V14)-W14 -> 4007930
B15: =L15 -> Rental income 2 (per week) | C15: =D15*12 -> 28600 | D15: =M15*52/12 -> 2383.3333 | E15: =D15-D22 -> 1538 | G15: Investment 2 (rental income) | H15: =C15/E46 -> 0.044 | L15: Rental income 2 (per week) | M15: 550 | P15: 9 | Q15: =Q14+30 -> 46331 | R15: =TEXT($Q15,"MMMM")&TEXT($Q15," YYYY") -> November 2026 | S15: =($V$1/12+1)*S14+T14 -> 3719088.8 | U15: =($V$2/12+1)*U14+$V$3 -> 887552.25 | V15: =V14+$I$56 -> 938173.31 | W15: =W14+X14 -> 1488000 | X15: =T15 -> 0 | Y15: =SUM(S15:V15)-W15 -> 4056814.3
P16: 10 | Q16: =Q15+30 -> 46361 | R16: =TEXT($Q16,"MMMM")&TEXT($Q16," YYYY") -> December 2026 | S16: =($V$1/12+1)*S15+T15 -> 3740783.5 | U16: =($V$2/12+1)*U15+$V$3 -> 899948.52 | V16: =V15+$I$56 -> 953194.98 | W16: =W15+X15 -> 1488000 | X16: =T16 -> 0 | Y16: =SUM(S16:V16)-W16 -> 4105927
G17: TOTAL INCOME | H17: (per month) | I17: =SUM(D6:D15) -> 25910 | P17: 11 | Q17: =Q16+30 -> 46391 | R17: =TEXT($Q17,"MMMM")&TEXT($Q17," YYYY") -> January 2027 | S17: =($V$1/12+1)*S16+T16 -> 3762604.7 | T17: =$V$4 -> 1000000 | U17: =($V$2/12+1)*U16+$V$3 -> 912448.09 | V17: =V16+$I$56 -> 968216.64 | W17: =W16+X16 -> 1488000 | X17: =T17 -> 1000000 | Y17: =SUM(S17:V17)-W17 -> 5155269.4
B18: EXPENSES | C18: PER YEAR | D18: PER MONTH | L18: EXPENSES | P18: 12 | Q18: =Q17+30 -> 46421 | R18: =TEXT($Q18,"MMMM")&TEXT($Q18," YYYY") -> February 2027 | S18: =($V$1/12+1)*S17+T17 -> 4784553.2 | U18: =($V$2/12+1)*U17+$V$3 -> 925051.82 | V18: =V17+$I$56 -> 983238.31 | W18: =W17+X17 -> 2488000 | X18: =T18 -> 0 | Y18: =SUM(S18:V18)-W18 -> 4204843.4
P19: 13 | Q19: =Q18+30 -> 46451 | R19: =TEXT($Q19,"MMMM")&TEXT($Q19," YYYY") -> March 2027 | S19: =($V$1/12+1)*S18+T18 -> 4812463.1 | U19: =($V$2/12+1)*U18+$V$3 -> 937760.59 | V19: =V18+$I$56 -> 998259.97 | W19: =W18+X18 -> 2488000 | X19: =T19 -> 0 | Y19: =SUM(S19:V19)-W19 -> 4260483.7
B20: Mortgage - Home per month | C20: =D20*12 -> 0 | D20: =M20 -> 0 | L20: HOME Mortgage (P+I) - per month | M20: 0 | P20: 14 | Q20: =Q19+30 -> 46481 | R20: =TEXT($Q20,"MMMM")&TEXT($Q20," YYYY") -> April 2027 | S20: =($V$1/12+1)*S19+T19 -> 4840535.8 | U20: =($V$2/12+1)*U19+$V$3 -> 950575.26 | V20: =V19+$I$56 -> 1013281.6 | W20: =W19+X19 -> 2488000 | X20: =T20 -> 0 | Y20: =SUM(S20:V20)-W20 -> 4316392.7
B21: =L21 -> Interest Forest Lake | C21: =D21*12 -> 32460.8 | D21: =M21*I45/12 -> 2705.0667 | L21: Interest Forest Lake | M21: 0.0634 | P21: 15 | Q21: =Q20+30 -> 46511 | R21: =TEXT($Q21,"MMMM")&TEXT($Q21," YYYY") -> May 2027 | S21: =($V$1/12+1)*S20+T20 -> 4868772.3 | U21: =($V$2/12+1)*U20+$V$3 -> 963496.72 | V21: =V20+$I$56 -> 1028303.3 | W21: =W20+X20 -> 2488000 | X21: =T21 -> 0 | Y21: =SUM(S21:V21)-W21 -> 4372572.3
B22: =L22 -> Interest Strathpine | C22: =D22*12 -> 10144 | D22: =M22*I46/12 -> 845.33333 | G22: CASH FLOW (monthly) | H22: =I17-I28 -> 15021.664 | L22: Interest Strathpine | M22: 0.0634 | P22: 16 | Q22: =Q21+30 -> 46541 | R22: =TEXT($Q22,"MMMM")&TEXT($Q22," YYYY") -> June 2027 | S22: =($V$1/12+1)*S21+T21 -> 4897173.5 | U22: =($V$2/12+1)*U21+$V$3 -> 976525.86 | V22: =V21+$I$56 -> 1043325 | W22: =W21+X21 -> 2488000 | X22: =T22 -> 0 | Y22: =SUM(S22:V22)-W22 -> 4429024.3
B23: LOC | C23: =D23*12 -> 0 | D23: =M23*I47/12 -> 0 | G23: Total Income - Total Expenses | L23: Investment 3, interest rate on debt | M23: 0 | P23: 17 | Q23: =Q22+30 -> 46571 | R23: =TEXT($Q23,"MMMM")&TEXT($Q23," YYYY") -> July 2027 | S23: =($V$1/12+1)*S22+T22 -> 4925740.3 | U23: =($V$2/12+1)*U22+$V$3 -> 989663.58 | V23: =V22+$I$56 -> 1058346.6 | W23: =W22+X22 -> 2488000 | X23: =T23 -> 0 | Y23: =SUM(S23:V23)-W23 -> 4485750.5
P24: 18 | Q24: =Q23+30 -> 46601 | R24: =TEXT($Q24,"MMMM")&TEXT($Q24," YYYY") -> August 2027 | S24: =($V$1/12+1)*S23+T23 -> 4954473.8 | U24: =($V$2/12+1)*U23+$V$3 -> 1002910.8 | V24: =V23+$I$56 -> 1073368.3 | W24: =W23+X23 -> 2488000 | X24: =T24 -> 0 | Y24: =SUM(S24:V24)-W24 -> 4542752.8
B25: Monthly Personal Expenses / Spending | C25: =D25*12 -> 88055.23 | D25: =SUM(M30:M36) -> 7337.9358 | P25: 19 | Q25: =Q24+30 -> 46631 | R25: =TEXT($Q25,"MMMM")&TEXT($Q25," YYYY") -> September 2027 | S25: =($V$1/12+1)*S24+T24 -> 4983374.9 | U25: =($V$2/12+1)*U24+$V$3 -> 1016268.4 | V25: =V24+$I$56 -> 1088390 | W25: =W24+X24 -> 2488000 | X25: =T25 -> 0 | Y25: =SUM(S25:V25)-W25 -> 4600033.2
B26: Rental Payment | C26: =D26*12 -> 0 | D26: ='Monthly Expenses Budget'!C10 -> 0 | L26: Other (Insert any other not covered) | P26: 20 | Q26: =Q25+30 -> 46661 | R26: =TEXT($Q26,"MMMM")&TEXT($Q26," YYYY") -> October 2027 | S26: =($V$1/12+1)*S25+T25 -> 5012444.6 | U26: =($V$2/12+1)*U25+$V$3 -> 1029737.3 | V26: =V25+$I$56 -> 1103411.6 | W26: =W25+X25 -> 2488000 | X26: =T26 -> 0 | Y26: =SUM(S26:V26)-W26 -> 4657593.5
B27: Other | D27: =M26 -> 0 | P27: 21 | Q27: =Q26+30 -> 46691 | R27: =TEXT($Q27,"MMMM")&TEXT($Q27," YYYY") -> October 2027 | S27: =($V$1/12+1)*S26+T26 -> 5041683.8 | U27: =($V$2/12+1)*U26+$V$3 -> 1043318.4 | V27: =V26+$I$56 -> 1118433.3 | W27: =W26+X26 -> 2488000 | X27: =T27 -> 0 | Y27: =SUM(S27:V27)-W27 -> 4715435.5
G28: TOTAL EXPENSES | H28: (per month) | I28: =SUM(D20:D27) -> 10888.336 | L28: From Budget Spreadsheet - DO NOT UPDATE THIS | M28: =SUM(M29:M36) -> 7337.9358 | P28: 22 | Q28: =Q27+30 -> 46721 | R28: =TEXT($Q28,"MMMM")&TEXT($Q28," YYYY") -> November 2027 | S28: =($V$1/12+1)*S27+T27 -> 5071093.6 | T28: =$V$4 -> 1000000 | U28: =($V$2/12+1)*U27+$V$3 -> 1057012.7 | V28: =V27+$I$56 -> 1133454.9 | W28: =W27+X27 -> 2488000 | X28: =T28 -> 1000000 | Y28: =SUM(S28:V28)-W28 -> 5773561.3
L29: ='Monthly Expenses Budget'!B5 -> Home and other Fixed Expenses | M29: ='Monthly Expenses Budget'!C5 -> 0 | P29: 23 | Q29: =Q28+30 -> 46751 | R29: =TEXT($Q29,"MMMM")&TEXT($Q29," YYYY") -> December 2027 | S29: =($V$1/12+1)*S28+T28 -> 6100675 | U29: =($V$2/12+1)*U28+$V$3 -> 1070821.2 | V29: =V28+$I$56 -> 1148476.6 | W29: =W28+X28 -> 3488000 | X29: =T29 -> 0 | Y29: =SUM(S29:V29)-W29 -> 4831972.8
B30: BALANCE SHEET | L30: ='Monthly Expenses Budget'!B12 -> Essentials | M30: ='Monthly Expenses Budget'!C12 -> 875.7325 | P30: 24 | Q30: =Q29+30 -> 46781 | R30: =TEXT($Q30,"MMMM")&TEXT($Q30," YYYY") -> January 2028 | S30: =($V$1/12+1)*S29+T29 -> 6136262.3 | U30: =($V$2/12+1)*U29+$V$3 -> 1084744.7 | V30: =V29+$I$56 -> 1163498.3 | W30: =W29+X29 -> 3488000 | X30: =T30 -> 0 | Y30: =SUM(S30:V30)-W30 -> 4896505.3
L31: ='Monthly Expenses Budget'!B22 -> Groceries | M31: ='Monthly Expenses Budget'!C22 -> 2120 | P31: 25 | Q31: =Q30+30 -> 46811 | R31: =TEXT($Q31,"MMMM")&TEXT($Q31," YYYY") -> February 2028 | S31: =($V$1/12+1)*S30+T30 -> 6172057.2 | U31: =($V$2/12+1)*U30+$V$3 -> 1098784.2 | V31: =V30+$I$56 -> 1178519.9 | W31: =W30+X30 -> 3488000 | X31: =T31 -> 0 | Y31: =SUM(S31:V31)-W31 -> 4961361.3
B32: ASSETS | E32: ASSET VALUE | G32: LIABILITIES (DEBT) | L32: ='Monthly Expenses Budget'!B31 -> House Maintenance | M32: ='Monthly Expenses Budget'!C31 -> 230 | P32: 26 | Q32: =Q31+30 -> 46841 | R32: =TEXT($Q32,"MMMM")&TEXT($Q32," YYYY") -> March 2028 | S32: =($V$1/12+1)*S31+T31 -> 6208060.8 | U32: =($V$2/12+1)*U31+$V$3 -> 1112940.8 | V32: =V31+$I$56 -> 1193541.6 | W32: =W31+X31 -> 3488000 | X32: =T32 -> 0 | Y32: =SUM(S32:V32)-W32 -> 5026543.2
L33: ='Monthly Expenses Budget'!B39 -> Health | M33: ='Monthly Expenses Budget'!C39 -> 1514.7033 | P33: 27 | Q33: =Q32+30 -> 46871 | R33: =TEXT($Q33,"MMMM")&TEXT($Q33," YYYY") -> April 2028 | S33: =($V$1/12+1)*S32+T32 -> 6244274.5 | U33: =($V$2/12+1)*U32+$V$3 -> 1127215.3 | V33: =V32+$I$56 -> 1208563.3 | W33: =W32+X32 -> 3488000 | X33: =T33 -> 0 | Y33: =SUM(S33:V33)-W33 -> 5092053
B34: Savings Account 1 | E34: =M40 -> 818000 | G34: Credit Card 1 (total limit) | I34: 10000 | L34: ='Monthly Expenses Budget'!B49 -> Discretionary | M34: ='Monthly Expenses Budget'!C49 -> 1100 | P34: 28 | Q34: =Q33+30 -> 46901 | R34: =TEXT($Q34,"MMMM")&TEXT($Q34," YYYY") -> May 2028 | S34: =($V$1/12+1)*S33+T33 -> 6280699.5 | U34: =($V$2/12+1)*U33+$V$3 -> 1141608.7 | V34: =V33+$I$56 -> 1223584.9 | W34: =W33+X33 -> 3488000 | X34: =T34 -> 0 | Y34: =SUM(S34:V34)-W34 -> 5157893.1
B35: Savings Account 2 | E35: =M41 -> 0 | G35: Credit Card 2 (total limit) | I35: 2000 | L35: ='Monthly Expenses Budget'!B58 -> Sports / Activities | M35: ='Monthly Expenses Budget'!C58 -> 397.5 | P35: 29 | Q35: =Q34+30 -> 46931 | R35: =TEXT($Q35,"MMMM")&TEXT($Q35," YYYY") -> June 2028 | S35: =($V$1/12+1)*S34+T34 -> 6317336.9 | U35: =($V$2/12+1)*U34+$V$3 -> 1156122.1 | V35: =V34+$I$56 -> 1238606.6 | W35: =W34+X34 -> 3488000 | X35: =T35 -> 0 | Y35: =SUM(S35:V35)-W35 -> 5224065.6
G36: Personal Loans | L36: ='Monthly Expenses Budget'!B64 -> Other | M36: ='Monthly Expenses Budget'!C64 -> 1100 | P36: 30 | Q36: =Q35+30 -> 46961 | R36: =TEXT($Q36,"MMMM")&TEXT($Q36," YYYY") -> July 2028 | S36: =($V$1/12+1)*S35+T35 -> 6354188 | U36: =($V$2/12+1)*U35+$V$3 -> 1170756.5 | V36: =V35+$I$56 -> 1253628.3 | W36: =W35+X35 -> 3488000 | X36: =T36 -> 0 | Y36: =SUM(S36:V36)-W36 -> 5290572.7
B37: Stocks (local) | E37: =M43 -> 183000 | G37: Other Loans | P37: 31 | Q37: =Q36+30 -> 46991 | R37: =TEXT($Q37,"MMMM")&TEXT($Q37," YYYY") -> August 2028 | S37: =($V$1/12+1)*S36+T36 -> 6391254.1 | U37: =($V$2/12+1)*U36+$V$3 -> 1185512.8 | V37: =V36+$I$56 -> 1268649.9 | W37: =W36+X36 -> 3488000 | X37: =T37 -> 0 | Y37: =SUM(S37:V37)-W37 -> 5357416.8
B38: Stocks (offshore) | E38: =M44 -> 194000 | P38: 32 | Q38: =Q37+30 -> 47021 | R38: =TEXT($Q38,"MMMM")&TEXT($Q38," YYYY") -> September 2028 | S38: =($V$1/12+1)*S37+T37 -> 6428536.4 | U38: =($V$2/12+1)*U37+$V$3 -> 1200392.1 | V38: =V37+$I$56 -> 1283671.6 | W38: =W37+X37 -> 3488000 | X38: =T38 -> 0 | Y38: =SUM(S38:V38)-W38 -> 5424600.1
B39: Other stocks | E39: =M45 -> 415000 | L39: ASSETS | P39: 33 | Q39: =Q38+30 -> 47051 | R39: =TEXT($Q39,"MMMM")&TEXT($Q39," YYYY") -> October 2028 | S39: =($V$1/12+1)*S38+T38 -> 6466036.2 | U39: =($V$2/12+1)*U38+$V$3 -> 1215395.3 | V39: =V38+$I$56 -> 1298693.3 | W39: =W38+X38 -> 3488000 | X39: =T39 -> 0 | Y39: =SUM(S39:V39)-W39 -> 5492124.8
L40: Savings (account 1) | M40: 818000 | P40: 34 | Q40: =Q39+30 -> 47081 | R40: =TEXT($Q40,"MMMM")&TEXT($Q40," YYYY") -> November 2028 | S40: =($V$1/12+1)*S39+T39 -> 6503754.8 | T40: =$V$4 -> 1000000 | U40: =($V$2/12+1)*U39+$V$3 -> 1230523.6 | V40: =V39+$I$56 -> 1313714.9 | W40: =W39+X39 -> 3488000 | X40: =T40 -> 1000000 | Y40: =SUM(S40:V40)-W40 -> 6559993.3
...

Sheet FV_May25
U1: Property Growth Rate (PY) | V1: 0.07
B2: INCOME STATEMENT | L2: INPUTS!!! Fill out the ORANGE cells ONLY | U2: Stock Growth Rate (PY) | V2: 0.1
U3: Stock contribution per month | V3: 5000 | AI3: NET GROWTH FORECAST
B4: INCOME | C4: PER YEAR | D4: PER MONTH | E4: PASSIVE PM | G4: PASSIVE | H4: PER MONTH | I4: PER YEAR | L4: INCOME | U4: Yearly Prop Purchase Value | V4: 1000000
G5: PASSIVE INCOME | H5: =SUM(E8:E15) -> 2494 | I5: =H5*12 -> 29928
B6: Salary 1 | C6: =D6*12 -> 276000 | D6: =M6 -> 23000 | L6: Salary 1 (ex tax per month) | M6: 23000 | P6: Date | Q6: Date | R6: Month | S6: Properties | T6: Add Prop | U6: Stocks | V6: Savings | W6: Liabilities | X6: Add Liab | Y6: Total Net Worth
B7: Salary 2 | C7: =D7*12 -> 0 | D7: =M7 -> 0 | L7: Salary 2 (ex tax per month) | P7: 1 | Q7: =TODAY() -> 46091 | R7: =TEXT($Q7,"MMMM")&TEXT($Q7," YYYY") -> March 2026 | S7: =SUM(E44:E46) -> 3550000 | U7: =SUM(E37:E39) -> 915000 | V7: =$E$34 -> 818000 | W7: =$I$50 -> 1488000 | X7: =T7 -> 0 | Y7: =SUM(S7:V7)-W7 -> 3795000
B8: Interest Earned (from savings) | D8: =M8 -> 10 | E8: =D8 -> 10 | L8: Interest from Savings (per month) | M8: 10 | P8: 2 | Q8: =Q7+30 -> 46121 | R8: =TEXT($Q8,"MMMM")&TEXT($Q8," YYYY") -> April 2026 | S8: =($V$1/12+1)*S7+T7 -> 3570708.3 | U8: =($V$2/12+1)*U7+$V$3 -> 927625 | V8: =V7+$I$56 -> 836156.06 | W8: =W7+X7 -> 1488000 | X8: =T8 -> 0 | Y8: =SUM(S8:V8)-W8 -> 3846489.4
B9: Dividends | D9: =M9 -> 830 | E9: =D9 -> 830 | L9: Income from Dividends (per month) | M9: 830 | P9: 3 | Q9: =Q8+30 -> 46151 | R9: =TEXT($Q9,"MMMM")&TEXT($Q9," YYYY") -> May 2026 | S9: =($V$1/12+1)*S8+T8 -> 3591537.5 | U9: =($V$2/12+1)*U8+$V$3 -> 940355.21 | V9: =V8+$I$56 -> 854312.13 | W9: =W8+X8 -> 1488000 | X9: =T9 -> 0 | Y9: =SUM(S9:V9)-W9 -> 3898204.8
B10: Other income | D10: =M10 -> 0 | L10: Any other income (per month) | M10: 0 | P10: 4 | Q10: =Q9+30 -> 46181 | R10: =TEXT($Q10,"MMMM")&TEXT($Q10," YYYY") -> June 2026 | S10: =($V$1/12+1)*S9+T9 -> 3612488.1 | U10: =($V$2/12+1)*U9+$V$3 -> 953191.5 | V10: =V9+$I$56 -> 872468.19 | W10: =W9+X9 -> 1488000 | X10: =T10 -> 0 | Y10: =SUM(S10:V10)-W10 -> 3950147.8
P11: 5 | Q11: =Q10+30 -> 46211 | R11: =TEXT($Q11,"MMMM")&TEXT($Q11," YYYY") -> July 2026 | S11: =($V$1/12+1)*S10+T10 -> 3633560.9 | U11: =($V$2/12+1)*U10+$V$3 -> 966134.76 | V11: =V10+$I$56 -> 890624.26 | W11: =W10+X10 -> 1488000 | X11: =T11 -> 0 | Y11: =SUM(S11:V11)-W11 -> 4002320
B12: Real Estate / Other income: | P12: 6 | Q12: =Q11+30 -> 46241 | R12: =TEXT($Q12,"MMMM")&TEXT($Q12," YYYY") -> August 2026 | S12: =($V$1/12+1)*S11+T11 -> 3654756.7 | U12: =($V$2/12+1)*U11+$V$3 -> 979185.89 | V12: =V11+$I$56 -> 908780.32 | W12: =W11+X11 -> 1488000 | X12: =T12 -> 0 | Y12: =SUM(S12:V12)-W12 -> 4054722.9
G13: Property Yield | H13: % | P13: 7 | Q13: =Q12+30 -> 46271 | R13: =TEXT($Q13,"MMMM")&TEXT($Q13," YYYY") -> September 2026 | S13: =($V$1/12+1)*S12+T12 -> 3676076.1 | U13: =($V$2/12+1)*U12+$V$3 -> 992345.77 | V13: =V12+$I$56 -> 926936.39 | W13: =W12+X12 -> 1488000 | X13: =T13 -> 0 | Y13: =SUM(S13:V13)-W13 -> 4107358.3
B14: =L14 -> Rental income 1 (per week) | C14: =D14*12 -> 32240 | D14: =M14*52/12 -> 2686.6667 | E14: =D14-D21 -> 84 | G14: Investment 1 (rental income) | H14: =C14/E45 -> 0.03224 | L14: Rental income 1 (per week) | M14: 620 | P14: 8 | Q14: =Q13+30 -> 46301 | R14: =TEXT($Q14,"MMMM")&TEXT($Q14," YYYY") -> October 2026 | S14: =($V$1/12+1)*S13+T13 -> 3697519.9 | U14: =($V$2/12+1)*U13+$V$3 -> 1005615.3 | V14: =V13+$I$56 -> 945092.45 | W14: =W13+X13 -> 1488000 | X14: =T14 -> 0 | Y14: =SUM(S14:V14)-W14 -> 4160227.7
B15: =L15 -> Rental income 2 (per week) | C15: =D15*12 -> 28600 | D15: =M15*52/12 -> 2383.3333 | E15: =D15-D22 -> 1570 | G15: Investment 2 (rental income) | H15: =C15/E46 -> 0.044 | L15: Rental income 2 (per week) | M15: 550 | P15: 9 | Q15: =Q14+30 -> 46331 | R15: =TEXT($Q15,"MMMM")&TEXT($Q15," YYYY") -> November 2026 | S15: =($V$1/12+1)*S14+T14 -> 3719088.8 | U15: =($V$2/12+1)*U14+$V$3 -> 1018995.4 | V15: =V14+$I$56 -> 963248.51 | W15: =W14+X14 -> 1488000 | X15: =T15 -> 0 | Y15: =SUM(S15:V15)-W15 -> 4213332.7
P16: 10 | Q16: =Q15+30 -> 46361 | R16: =TEXT($Q16,"MMMM")&TEXT($Q16," YYYY") -> December 2026 | S16: =($V$1/12+1)*S15+T15 -> 3740783.5 | U16: =($V$2/12+1)*U15+$V$3 -> 1032487.1 | V16: =V15+$I$56 -> 981404.58 | W16: =W15+X15 -> 1488000 | X16: =T16 -> 0 | Y16: =SUM(S16:V16)-W16 -> 4266675.1
G17: TOTAL INCOME | H17: (per month) | I17: =SUM(D6:D15) -> 28910 | P17: 11 | Q17: =Q16+30 -> 46391 | R17: =TEXT($Q17,"MMMM")&TEXT($Q17," YYYY") -> January 2027 | S17: =($V$1/12+1)*S16+T16 -> 3762604.7 | T17: =$V$4 -> 1000000 | U17: =($V$2/12+1)*U16+$V$3 -> 1046091.1 | V17: =V16+$I$56 -> 999560.64 | W17: =W16+X16 -> 1488000 | X17: =T17 -> 1000000 | Y17: =SUM(S17:V17)-W17 -> 5320256.5
B18: EXPENSES | C18: PER YEAR | D18: PER MONTH | L18: EXPENSES | P18: 12 | Q18: =Q17+30 -> 46421 | R18: =TEXT($Q18,"MMMM")&TEXT($Q18," YYYY") -> February 2027 | S18: =($V$1/12+1)*S17+T17 -> 4784553.2 | U18: =($V$2/12+1)*U17+$V$3 -> 1059808.6 | V18: =V17+$I$56 -> 1017716.7 | W18: =W17+X17 -> 2488000 | X18: =T18 -> 0 | Y18: =SUM(S18:V18)-W18 -> 4374078.5
P19: 13 | Q19: =Q18+30 -> 46451 | R19: =TEXT($Q19,"MMMM")&TEXT($Q19," YYYY") -> March 2027 | S19: =($V$1/12+1)*S18+T18 -> 4812463.1 | U19: =($V$2/12+1)*U18+$V$3 -> 1073640.3 | V19: =V18+$I$56 -> 1035872.8 | W19: =W18+X18 -> 2488000 | X19: =T19 -> 0 | Y19: =SUM(S19:V19)-W19 -> 4433976.2
B20: Mortgage - Home per month | C20: =D20*12 -> 0 | D20: =M20 -> 0 | L20: HOME Mortgage (P+I) - per month | M20: 0 | P20: 14 | Q20: =Q19+30 -> 46481 | R20: =TEXT($Q20,"MMMM")&TEXT($Q20," YYYY") -> April 2027 | S20: =($V$1/12+1)*S19+T19 -> 4840535.8 | U20: =($V$2/12+1)*U19+$V$3 -> 1087587.3 | V20: =V19+$I$56 -> 1054028.8 | W20: =W19+X19 -> 2488000 | X20: =T20 -> 0 | Y20: =SUM(S20:V20)-W20 -> 4494152
B21: =L21 -> Interest Forest Lake | C21: =D21*12 -> 31232 | D21: =M21*I45/12 -> 2602.6667 | L21: Interest Forest Lake | M21: 0.061 | P21: 15 | Q21: =Q20+30 -> 46511 | R21: =TEXT($Q21,"MMMM")&TEXT($Q21," YYYY") -> May 2027 | S21: =($V$1/12+1)*S20+T20 -> 4868772.3 | U21: =($V$2/12+1)*U20+$V$3 -> 1101650.5 | V21: =V20+$I$56 -> 1072184.9 | W21: =W20+X20 -> 2488000 | X21: =T21 -> 0 | Y21: =SUM(S21:V21)-W21 -> 4554607.7
B22: =L22 -> Interest Strathpine | C22: =D22*12 -> 9760 | D22: =M22*I46/12 -> 813.33333 | G22: CASH FLOW (monthly) | H22: =I17-I28 -> 18156.064 | L22: Interest Strathpine | M22: 0.061 | P22: 16 | Q22: =Q21+30 -> 46541 | R22: =TEXT($Q22,"MMMM")&TEXT($Q22," YYYY") -> June 2027 | S22: =($V$1/12+1)*S21+T21 -> 4897173.5 | U22: =($V$2/12+1)*U21+$V$3 -> 1115830.9 | V22: =V21+$I$56 -> 1090341 | W22: =W21+X21 -> 2488000 | X22: =T22 -> 0 | Y22: =SUM(S22:V22)-W22 -> 4615345.4
B23: LOC | C23: =D23*12 -> 0 | D23: =M23*I47/12 -> 0 | G23: Total Income - Total Expenses | L23: Investment 3, interest rate on debt | M23: 0 | P23: 17 | Q23: =Q22+30 -> 46571 | R23: =TEXT($Q23,"MMMM")&TEXT($Q23," YYYY") -> July 2027 | S23: =($V$1/12+1)*S22+T22 -> 4925740.3 | U23: =($V$2/12+1)*U22+$V$3 -> 1130129.5 | V23: =V22+$I$56 -> 1108497 | W23: =W22+X22 -> 2488000 | X23: =T23 -> 0 | Y23: =SUM(S23:V23)-W23 -> 4676366.9
P24: 18 | Q24: =Q23+30 -> 46601 | R24: =TEXT($Q24,"MMMM")&TEXT($Q24," YYYY") -> August 2027 | S24: =($V$1/12+1)*S23+T23 -> 4954473.8 | U24: =($V$2/12+1)*U23+$V$3 -> 1144547.3 | V24: =V23+$I$56 -> 1126653.1 | W24: =W23+X23 -> 2488000 | X24: =T24 -> 0 | Y24: =SUM(S24:V24)-W24 -> 4737674.2
B25: Monthly Personal Expenses / Spending | C25: =D25*12 -> 88055.23 | D25: =SUM(M30:M36) -> 7337.9358 | P25: 19 | Q25: =Q24+30 -> 46631 | R25: =TEXT($Q25,"MMMM")&TEXT($Q25," YYYY") -> September 2027 | S25: =($V$1/12+1)*S24+T24 -> 4983374.9 | U25: =($V$2/12+1)*U24+$V$3 -> 1159085.2 | V25: =V24+$I$56 -> 1144809.2 | W25: =W24+X24 -> 2488000 | X25: =T25 -> 0 | Y25: =SUM(S25:V25)-W25 -> 4799269.2
B26: Rental Payment | C26: =D26*12 -> 0 | D26: ='Monthly Expenses Budget'!C10 -> 0 | L26: Other (Insert any other not covered) | P26: 20 | Q26: =Q25+30 -> 46661 | R26: =TEXT($Q26,"MMMM")&TEXT($Q26," YYYY") -> October 2027 | S26: =($V$1/12+1)*S25+T25 -> 5012444.6 | U26: =($V$2/12+1)*U25+$V$3 -> 1173744.2 | V26: =V25+$I$56 -> 1162965.2 | W26: =W25+X25 -> 2488000 | X26: =T26 -> 0 | Y26: =SUM(S26:V26)-W26 -> 4861154
B27: Other | D27: =M26 -> 0 | P27: 21 | Q27: =Q26+30 -> 46691 | R27: =TEXT($Q27,"MMMM")&TEXT($Q27," YYYY") -> October 2027 | S27: =($V$1/12+1)*S26+T26 -> 5041683.8 | U27: =($V$2/12+1)*U26+$V$3 -> 1188525.4 | V27: =V26+$I$56 -> 1181121.3 | W27: =W26+X26 -> 2488000 | X27: =T27 -> 0 | Y27: =SUM(S27:V27)-W27 -> 4923330.5
G28: TOTAL EXPENSES | H28: (per month) | I28: =SUM(D20:D27) -> 10753.936 | L28: From Budget Spreadsheet - DO NOT UPDATE THIS | M28: =SUM(M29:M36) -> 7337.9358 | P28: 22 | Q28: =Q27+30 -> 46721 | R28: =TEXT($Q28,"MMMM")&TEXT($Q28," YYYY") -> November 2027 | S28: =($V$1/12+1)*S27+T27 -> 5071093.6 | T28: =$V$4 -> 1000000 | U28: =($V$2/12+1)*U27+$V$3 -> 1203429.8 | V28: =V27+$I$56 -> 1199277.3 | W28: =W27+X27 -> 2488000 | X28: =T28 -> 1000000 | Y28: =SUM(S28:V28)-W28 -> 5985800.8
L29: ='Monthly Expenses Budget'!B5 -> Home and other Fixed Expenses | M29: ='Monthly Expenses Budget'!C5 -> 0 | P29: 23 | Q29: =Q28+30 -> 46751 | R29: =TEXT($Q29,"MMMM")&TEXT($Q29," YYYY") -> December 2027 | S29: =($V$1/12+1)*S28+T28 -> 6100675 | U29: =($V$2/12+1)*U28+$V$3 -> 1218458.4 | V29: =V28+$I$56 -> 1217433.4 | W29: =W28+X28 -> 3488000 | X29: =T29 -> 0 | Y29: =SUM(S29:V29)-W29 -> 5048566.8
B30: BALANCE SHEET | L30: ='Monthly Expenses Budget'!B12 -> Essentials | M30: ='Monthly Expenses Budget'!C12 -> 875.7325 | P30: 24 | Q30: =Q29+30 -> 46781 | R30: =TEXT($Q30,"MMMM")&TEXT($Q30," YYYY") -> January 2028 | S30: =($V$1/12+1)*S29+T29 -> 6136262.3 | U30: =($V$2/12+1)*U29+$V$3 -> 1233612.2 | V30: =V29+$I$56 -> 1235589.5 | W30: =W29+X29 -> 3488000 | X30: =T30 -> 0 | Y30: =SUM(S30:V30)-W30 -> 5117464
L31: ='Monthly Expenses Budget'!B22 -> Groceries | M31: ='Monthly Expenses Budget'!C22 -> 2120 | P31: 25 | Q31: =Q30+30 -> 46811 | R31: =TEXT($Q31,"MMMM")&TEXT($Q31," YYYY") -> February 2028 | S31: =($V$1/12+1)*S30+T30 -> 6172057.2 | U31: =($V$2/12+1)*U30+$V$3 -> 1248892.3 | V31: =V30+$I$56 -> 1253745.5 | W31: =W30+X30 -> 3488000 | X31: =T31 -> 0 | Y31: =SUM(S31:V31)-W31 -> 5186695
B32: ASSETS | E32: ASSET VALUE | G32: LIABILITIES (DEBT) | L32: ='Monthly Expenses Budget'!B31 -> House Maintenance | M32: ='Monthly Expenses Budget'!C31 -> 230 | P32: 26 | Q32: =Q31+30 -> 46841 | R32: =TEXT($Q32,"MMMM")&TEXT($Q32," YYYY") -> March 2028 | S32: =($V$1/12+1)*S31+T31 -> 6208060.8 | U32: =($V$2/12+1)*U31+$V$3 -> 1264299.7 | V32: =V31+$I$56 -> 1271901.6 | W32: =W31+X31 -> 3488000 | X32: =T32 -> 0 | Y32: =SUM(S32:V32)-W32 -> 5256262.2
L33: ='Monthly Expenses Budget'!B39 -> Health | M33: ='Monthly Expenses Budget'!C39 -> 1514.7033 | P33: 27 | Q33: =Q32+30 -> 46871 | R33: =TEXT($Q33,"MMMM")&TEXT($Q33," YYYY") -> April 2028 | S33: =($V$1/12+1)*S32+T32 -> 6244274.5 | U33: =($V$2/12+1)*U32+$V$3 -> 1279835.6 | V33: =V32+$I$56 -> 1290057.7 | W33: =W32+X32 -> 3488000 | X33: =T33 -> 0 | Y33: =SUM(S33:V33)-W33 -> 5326167.8
B34: Savings Account 1 | E34: =M40 -> 818000 | G34: Credit Card 1 (total limit) | I34: 10000 | L34: ='Monthly Expenses Budget'!B49 -> Discretionary | M34: ='Monthly Expenses Budget'!C49 -> 1100 | P34: 28 | Q34: =Q33+30 -> 46901 | R34: =TEXT($Q34,"MMMM")&TEXT($Q34," YYYY") -> May 2028 | S34: =($V$1/12+1)*S33+T33 -> 6280699.5 | U34: =($V$2/12+1)*U33+$V$3 -> 1295500.9 | V34: =V33+$I$56 -> 1308213.7 | W34: =W33+X33 -> 3488000 | X34: =T34 -> 0 | Y34: =SUM(S34:V34)-W34 -> 5396414.1
B35: Savings Account 2 | E35: =M41 -> 0 | G35: Credit Card 2 (total limit) | I35: 2000 | L35: ='Monthly Expenses Budget'!B58 -> Sports / Activities | M35: ='Monthly Expenses Budget'!C58 -> 397.5 | P35: 29 | Q35: =Q34+30 -> 46931 | R35: =TEXT($Q35,"MMMM")&TEXT($Q35," YYYY") -> June 2028 | S35: =($V$1/12+1)*S34+T34 -> 6317336.9 | U35: =($V$2/12+1)*U34+$V$3 -> 1311296.7 | V35: =V34+$I$56 -> 1326369.8 | W35: =W34+X34 -> 3488000 | X35: =T35 -> 0 | Y35: =SUM(S35:V35)-W35 -> 5467003.4
G36: Personal Loans | L36: ='Monthly Expenses Budget'!B64 -> Other | M36: ='Monthly Expenses Budget'!C64 -> 1100 | P36: 30 | Q36: =Q35+30 -> 46961 | R36: =TEXT($Q36,"MMMM")&TEXT($Q36," YYYY") -> July 2028 | S36: =($V$1/12+1)*S35+T35 -> 6354188 | U36: =($V$2/12+1)*U35+$V$3 -> 1327224.2 | V36: =V35+$I$56 -> 1344525.9 | W36: =W35+X35 -> 3488000 | X36: =T36 -> 0 | Y36: =SUM(S36:V36)-W36 -> 5537938
B37: Stocks (local) | E37: =M43 -> 183000 | G37: Other Loans | P37: 31 | Q37: =Q36+30 -> 46991 | R37: =TEXT($Q37,"MMMM")&TEXT($Q37," YYYY") -> August 2028 | S37: =($V$1/12+1)*S36+T36 -> 6391254.1 | U37: =($V$2/12+1)*U36+$V$3 -> 1343284.4 | V37: =V36+$I$56 -> 1362681.9 | W37: =W36+X36 -> 3488000 | X37: =T37 -> 0 | Y37: =SUM(S37:V37)-W37 -> 5609220.4
B38: Stocks (offshore) | E38: =M44 -> 202000 | P38: 32 | Q38: =Q37+30 -> 47021 | R38: =TEXT($Q38,"MMMM")&TEXT($Q38," YYYY") -> September 2028 | S38: =($V$1/12+1)*S37+T37 -> 6428536.4 | U38: =($V$2/12+1)*U37+$V$3 -> 1359478.4 | V38: =V37+$I$56 -> 1380838 | W38: =W37+X37 -> 3488000 | X38: =T38 -> 0 | Y38: =SUM(S38:V38)-W38 -> 5680852.8
B39: Other stocks | E39: =M45 -> 530000 | L39: ASSETS | P39: 33 | Q39: =Q38+30 -> 47051 | R39: =TEXT($Q39,"MMMM")&TEXT($Q39," YYYY") -> October 2028 | S39: =($V$1/12+1)*S38+T38 -> 6466036.2 | U39: =($V$2/12+1)*U38+$V$3 -> 1375807.4 | V39: =V38+$I$56 -> 1398994.1 | W39: =W38+X38 -> 3488000 | X39: =T39 -> 0 | Y39: =SUM(S39:V39)-W39 -> 5752837.7
L40: Savings (account 1) | M40: 818000 | P40: 34 | Q40: =Q39+30 -> 47081 | R40: =TEXT($Q40,"MMMM")&TEXT($Q40," YYYY") -> November 2028 | S40: =($V$1/12+1)*S39+T39 -> 6503754.8 | T40: =$V$4 -> 1000000 | U40: =($V$2/12+1)*U39+$V$3 -> 1392272.5 | V40: =V39+$I$56 -> 1417150.1 | W40: =W39+X39 -> 3488000 | X40: =T40 -> 1000000 | Y40: =SUM(S40:V40)-W40 -> 6825177.3
...

Sheet FV_June25
U1: Property Growth Rate (PY) | V1: 0.07
B2: INCOME STATEMENT | L2: INPUTS!!! Fill out the ORANGE cells ONLY | U2: Stock Growth Rate (PY) | V2: 0.1
U3: Stock contribution per month | V3: 10000 | AI3: NET GROWTH FORECAST
B4: INCOME | C4: PER YEAR | D4: PER MONTH | E4: PASSIVE PM | G4: PASSIVE | H4: PER MONTH | I4: PER YEAR | L4: INCOME | U4: Yearly Prop Purchase Value | V4: 3000000
G5: PASSIVE INCOME | H5: =SUM(E8:E16) -> 1996.0167 | I5: =H5*12 -> 23952.2
B6: Salary 1 | C6: =D6*12 -> 276000 | D6: =M6 -> 23000 | L6: Salary 1 (ex tax per month) | M6: 23000 | P6: Date | Q6: Date | R6: Month | S6: Properties | T6: Add Prop | U6: Stocks | V6: Savings | W6: Liabilities | X6: Add Liab | Y6: Total Net Worth
B7: Salary 2 | C7: =D7*12 -> 0 | D7: =M7 -> 0 | L7: Salary 2 (ex tax per month) | P7: 1 | Q7: =TODAY() -> 46091 | R7: =TEXT($Q7,"MMMM")&TEXT($Q7," YYYY") -> March 2026 | S7: =SUM(E44:E47) -> 4175000 | U7: =SUM(E37:E39) -> 924000 | V7: =$E$34 -> 106000 | W7: =$I$50 -> 1524000 | X7: =T7 -> 0 | Y7: =SUM(S7:V7)-W7 -> 3681000
B8: Interest Earned (from savings) | D8: =M8 -> 10 | E8: =D8 -> 10 | L8: Interest from Savings (per month) | M8: 10 | P8: 2 | Q8: =Q7+30 -> 46121 | R8: =TEXT($Q8,"MMMM")&TEXT($Q8," YYYY") -> April 2026 | S8: =($V$1/12+1)*S7+T7 -> 4199354.2 | U8: =($V$2/12+1)*U7+$V$3 -> 941700 | V8: =V7+$I$56 -> 123658.08 | W8: =W7+X7 -> 1524000 | X8: =T8 -> 0 | Y8: =SUM(S8:V8)-W8 -> 3740712.2
B9: Dividends | D9: =M9 -> 830 | E9: =D9 -> 830 | L9: Income from Dividends (per month) | M9: 830 | P9: 3 | Q9: =Q8+30 -> 46151 | R9: =TEXT($Q9,"MMMM")&TEXT($Q9," YYYY") -> May 2026 | S9: =($V$1/12+1)*S8+T8 -> 4223850.4 | U9: =($V$2/12+1)*U8+$V$3 -> 959547.5 | V9: =V8+$I$56 -> 141316.16 | W9: =W8+X8 -> 1524000 | X9: =T9 -> 0 | Y9: =SUM(S9:V9)-W9 -> 3800714.1
B10: Other income | D10: =M10 -> 0 | L10: Any other income (per month) | M10: 0 | P10: 4 | Q10: =Q9+30 -> 46181 | R10: =TEXT($Q10,"MMMM")&TEXT($Q10," YYYY") -> June 2026 | S10: =($V$1/12+1)*S9+T9 -> 4248489.5 | U10: =($V$2/12+1)*U9+$V$3 -> 977543.73 | V10: =V9+$I$56 -> 158974.24 | W10: =W9+X9 -> 1524000 | X10: =T10 -> 0 | Y10: =SUM(S10:V10)-W10 -> 3861007.5
P11: 5 | Q11: =Q10+30 -> 46211 | R11: =TEXT($Q11,"MMMM")&TEXT($Q11," YYYY") -> July 2026 | S11: =($V$1/12+1)*S10+T10 -> 4273272.4 | U11: =($V$2/12+1)*U10+$V$3 -> 995689.93 | V11: =V10+$I$56 -> 176632.32 | W11: =W10+X10 -> 1524000 | X11: =T11 -> 0 | Y11: =SUM(S11:V11)-W11 -> 3921594.6
B12: Real Estate / Other income: | G12: Property Yield | H12: % | P12: 6 | Q12: =Q11+30 -> 46241 | R12: =TEXT($Q12,"MMMM")&TEXT($Q12," YYYY") -> August 2026 | S12: =($V$1/12+1)*S11+T11 -> 4298199.8 | U12: =($V$2/12+1)*U11+$V$3 -> 1013987.3 | V12: =V11+$I$56 -> 194290.4 | W12: =W11+X11 -> 1524000 | X12: =T12 -> 0 | Y12: =SUM(S12:V12)-W12 -> 3982477.6
G13: Investment 1 (rental income) | H13: =C14/E45 -> 0.033936842 | P13: 7 | Q13: =Q12+30 -> 46271 | R13: =TEXT($Q13,"MMMM")&TEXT($Q13," YYYY") -> September 2026 | S13: =($V$1/12+1)*S12+T12 -> 4323272.6 | U13: =($V$2/12+1)*U12+$V$3 -> 1032437.2 | V13: =V12+$I$56 -> 211948.49 | W13: =W12+X12 -> 1524000 | X13: =T13 -> 0 | Y13: =SUM(S13:V13)-W13 -> 4043658.4
B14: =L14 -> Rental income Forest Lake (per week) | C14: =D14*12 -> 32240 | D14: =M14*52/12 -> 2686.6667 | E14: =D14-D21 -> 130.93333 | G14: Investment 2 (rental income) | H14: =C15/E46 -> 0.060666667 | L14: Rental income Forest Lake (per week) | M14: 620 | P14: 8 | Q14: =Q13+30 -> 46301 | R14: =TEXT($Q14,"MMMM")&TEXT($Q14," YYYY") -> October 2026 | S14: =($V$1/12+1)*S13+T13 -> 4348491.7 | U14: =($V$2/12+1)*U13+$V$3 -> 1051040.9 | V14: =V13+$I$56 -> 229606.57 | W14: =W13+X13 -> 1524000 | X14: =T14 -> 0 | Y14: =SUM(S14:V14)-W14 -> 4105139.2
B15: =L15 -> Rental income Strathpine (per week) | C15: =D15*12 -> 36400 | D15: =M15*52/12 -> 3033.3333 | E15: =D15-D22 -> 1885.25 | G15: Investment 3 (rental income) | H15: =C16/E47 -> 0.050206897 | L15: Rental income Strathpine (per week) | M15: 700 | P15: 9 | Q15: =Q14+30 -> 46331 | R15: =TEXT($Q15,"MMMM")&TEXT($Q15," YYYY") -> November 2026 | S15: =($V$1/12+1)*S14+T14 -> 4373857.9 | U15: =($V$2/12+1)*U14+$V$3 -> 1069799.6 | V15: =V14+$I$56 -> 247264.65 | W15: =W14+X14 -> 1524000 | X15: =T15 -> 0 | Y15: =SUM(S15:V15)-W15 -> 4166922.1
B16: =L16 -> Rental income Mt Sheridan (per week) | C16: =D16*12 -> 36400 | D16: =M16*52/12 -> 3033.3333 | E16: =D16-D23 -> -860.16667 | L16: Rental income Mt Sheridan (per week) | M16: 700 | P16: 10 | Q16: =Q15+30 -> 46361 | R16: =TEXT($Q16,"MMMM")&TEXT($Q16," YYYY") -> December 2026 | S16: =($V$1/12+1)*S15+T15 -> 4399372.1 | U16: =($V$2/12+1)*U15+$V$3 -> 1088714.6 | V16: =V15+$I$56 -> 264922.73 | W16: =W15+X15 -> 1524000 | X16: =T16 -> 0 | Y16: =SUM(S16:V16)-W16 -> 4229009.4
G17: TOTAL INCOME | H17: (per month) | I17: =SUM(D6:D16) -> 32593.333 | P17: 11 | Q17: =Q16+30 -> 46391 | R17: =TEXT($Q17,"MMMM")&TEXT($Q17," YYYY") -> January 2027 | S17: =($V$1/12+1)*S16+T16 -> 4425035.1 | T17: =$V$4 -> 3000000 | U17: =($V$2/12+1)*U16+$V$3 -> 1107787.2 | V17: =V16+$I$56 -> 282580.81 | W17: =W16+X16 -> 1524000 | X17: =T17 -> 3000000 | Y17: =SUM(S17:V17)-W17 -> 7291403.1
B18: EXPENSES | C18: PER YEAR | D18: PER MONTH | L18: EXPENSES | P18: 12 | Q18: =Q17+30 -> 46421 | R18: =TEXT($Q18,"MMMM")&TEXT($Q18," YYYY") -> February 2027 | S18: =($V$1/12+1)*S17+T17 -> 7450847.8 | U18: =($V$2/12+1)*U17+$V$3 -> 1127018.7 | V18: =V17+$I$56 -> 300238.89 | W18: =W17+X17 -> 4524000 | X18: =T18 -> 0 | Y18: =SUM(S18:V18)-W18 -> 4354105.4
P19: 13 | Q19: =Q18+30 -> 46451 | R19: =TEXT($Q19,"MMMM")&TEXT($Q19," YYYY") -> March 2027 | S19: =($V$1/12+1)*S18+T18 -> 7494311.1 | U19: =($V$2/12+1)*U18+$V$3 -> 1146410.6 | V19: =V18+$I$56 -> 317896.97 | W19: =W18+X18 -> 4524000 | X19: =T19 -> 0 | Y19: =SUM(S19:V19)-W19 -> 4434618.6
B20: Mortgage - Home per month | C20: =D20*12 -> 0 | D20: =M20 -> 0 | L20: HOME Mortgage (P+I) - per month | M20: 0 | P20: 14 | Q20: =Q19+30 -> 46481 | R20: =TEXT($Q20,"MMMM")&TEXT($Q20," YYYY") -> April 2027 | S20: =($V$1/12+1)*S19+T19 -> 7538027.9 | U20: =($V$2/12+1)*U19+$V$3 -> 1165964 | V20: =V19+$I$56 -> 335555.05 | W20: =W19+X19 -> 4524000 | X20: =T20 -> 0 | Y20: =SUM(S20:V20)-W20 -> 4515546.9
B21: =L21 -> Interest Forest Lake | C21: =D21*12 -> 30668.8 | D21: =M21*I45/12 -> 2555.7333 | L21: Interest Forest Lake | M21: 0.0599 | P21: 15 | Q21: =Q20+30 -> 46511 | R21: =TEXT($Q21,"MMMM")&TEXT($Q21," YYYY") -> May 2027 | S21: =($V$1/12+1)*S20+T20 -> 7581999.7 | U21: =($V$2/12+1)*U20+$V$3 -> 1185680.3 | V21: =V20+$I$56 -> 353213.13 | W21: =W20+X20 -> 4524000 | X21: =T21 -> 0 | Y21: =SUM(S21:V21)-W21 -> 4596893.2
B22: =L22 -> Interest Strathpine | C22: =D22*12 -> 13777 | D22: =M22*I46/12 -> 1148.0833 | G22: CASH FLOW (monthly) | H22: =I17-I28 -> 17658.081 | L22: Interest Strathpine | M22: 0.0599 | P22: 16 | Q22: =Q21+30 -> 46541 | R22: =TEXT($Q22,"MMMM")&TEXT($Q22," YYYY") -> June 2027 | S22: =($V$1/12+1)*S21+T21 -> 7626228.1 | U22: =($V$2/12+1)*U21+$V$3 -> 1205561 | V22: =V21+$I$56 -> 370871.21 | W22: =W21+X21 -> 4524000 | X22: =T22 -> 0 | Y22: =SUM(S22:V22)-W22 -> 4678660.3
B23: Interest Mt Sheridan | C23: =D23*12 -> 46722 | D23: =M23*I47/12 -> 3893.5 | G23: Total Income - Total Expenses | L23: Invest Mt Sheridan | M23: 0.0599 | P23: 17 | Q23: =Q22+30 -> 46571 | R23: =TEXT($Q23,"MMMM")&TEXT($Q23," YYYY") -> July 2027 | S23: =($V$1/12+1)*S22+T22 -> 7670714.4 | U23: =($V$2/12+1)*U22+$V$3 -> 1225607.4 | V23: =V22+$I$56 -> 388529.29 | W23: =W22+X22 -> 4524000 | X23: =T23 -> 0 | Y23: =SUM(S23:V23)-W23 -> 4760851
P24: 18 | Q24: =Q23+30 -> 46601 | R24: =TEXT($Q24,"MMMM")&TEXT($Q24," YYYY") -> August 2027 | S24: =($V$1/12+1)*S23+T23 -> 7715460.2 | U24: =($V$2/12+1)*U23+$V$3 -> 1245820.7 | V24: =V23+$I$56 -> 406187.37 | W24: =W23+X23 -> 4524000 | X24: =T24 -> 0 | Y24: =SUM(S24:V24)-W24 -> 4843468.4
B25: Monthly Personal Expenses / Spending | C25: =D25*12 -> 88055.23 | D25: =SUM(M30:M36) -> 7337.9358 | P25: 19 | Q25: =Q24+30 -> 46631 | R25: =TEXT($Q25,"MMMM")&TEXT($Q25," YYYY") -> September 2027 | S25: =($V$1/12+1)*S24+T24 -> 7760467.1 | U25: =($V$2/12+1)*U24+$V$3 -> 1266202.6 | V25: =V24+$I$56 -> 423845.45 | W25: =W24+X24 -> 4524000 | X25: =T25 -> 0 | Y25: =SUM(S25:V25)-W25 -> 4926515.1
B26: Rental Payment | C26: =D26*12 -> 0 | D26: ='Monthly Expenses Budget'!C10 -> 0 | L26: Other (Insert any other not covered) | P26: 20 | Q26: =Q25+30 -> 46661 | R26: =TEXT($Q26,"MMMM")&TEXT($Q26," YYYY") -> October 2027 | S26: =($V$1/12+1)*S25+T25 -> 7805736.5 | U26: =($V$2/12+1)*U25+$V$3 -> 1286754.3 | V26: =V25+$I$56 -> 441503.54 | W26: =W25+X25 -> 4524000 | X26: =T26 -> 0 | Y26: =SUM(S26:V26)-W26 -> 5009994.3
B27: Other | D27: =M26 -> 0 | P27: 21 | Q27: =Q26+30 -> 46691 | R27: =TEXT($Q27,"MMMM")&TEXT($Q27," YYYY") -> October 2027 | S27: =($V$1/12+1)*S26+T26 -> 7851269.9 | U27: =($V$2/12+1)*U26+$V$3 -> 1307477.2 | V27: =V26+$I$56 -> 459161.62 | W27: =W26+X26 -> 4524000 | X27: =T27 -> 0 | Y27: =SUM(S27:V27)-W27 -> 5093908.8
G28: TOTAL EXPENSES | H28: (per month) | I28: =SUM(D20:D27) -> 14935.252 | L28: From Budget Spreadsheet - DO NOT UPDATE THIS | M28: =SUM(M29:M36) -> 7337.9358 | P28: 22 | Q28: =Q27+30 -> 46721 | R28: =TEXT($Q28,"MMMM")&TEXT($Q28," YYYY") -> November 2027 | S28: =($V$1/12+1)*S27+T27 -> 7897069 | T28: =$V$4 -> 3000000 | U28: =($V$2/12+1)*U27+$V$3 -> 1328372.9 | V28: =V27+$I$56 -> 476819.7 | W28: =W27+X27 -> 4524000 | X28: =T28 -> 3000000 | Y28: =SUM(S28:V28)-W28 -> 8178261.6
L29: ='Monthly Expenses Budget'!B5 -> Home and other Fixed Expenses | M29: ='Monthly Expenses Budget'!C5 -> 0 | P29: 23 | Q29: =Q28+30 -> 46751 | R29: =TEXT($Q29,"MMMM")&TEXT($Q29," YYYY") -> December 2027 | S29: =($V$1/12+1)*S28+T28 -> 10943135 | U29: =($V$2/12+1)*U28+$V$3 -> 1349442.6 | V29: =V28+$I$56 -> 494477.78 | W29: =W28+X28 -> 7524000 | X29: =T29 -> 0 | Y29: =SUM(S29:V29)-W29 -> 5263055.7
B30: BALANCE SHEET | L30: ='Monthly Expenses Budget'!B12 -> Essentials | M30: ='Monthly Expenses Budget'!C12 -> 875.7325 | P30: 24 | Q30: =Q29+30 -> 46781 | R30: =TEXT($Q30,"MMMM")&TEXT($Q30," YYYY") -> January 2028 | S30: =($V$1/12+1)*S29+T29 -> 11006970 | U30: =($V$2/12+1)*U29+$V$3 -> 1370688 | V30: =V29+$I$56 -> 512135.86 | W30: =W29+X29 -> 7524000 | X30: =T30 -> 0 | Y30: =SUM(S30:V30)-W30 -> 5365794.1
L31: ='Monthly Expenses Budget'!B22 -> Groceries | M31: ='Monthly Expenses Budget'!C22 -> 2120 | P31: 25 | Q31: =Q30+30 -> 46811 | R31: =TEXT($Q31,"MMMM")&TEXT($Q31," YYYY") -> February 2028 | S31: =($V$1/12+1)*S30+T30 -> 11071178 | U31: =($V$2/12+1)*U30+$V$3 -> 1392110.4 | V31: =V30+$I$56 -> 529793.94 | W31: =W30+X30 -> 7524000 | X31: =T31 -> 0 | Y31: =SUM(S31:V31)-W31 -> 5469081.9
B32: ASSETS | E32: ASSET VALUE | G32: LIABILITIES (DEBT) | L32: ='Monthly Expenses Budget'!B31 -> House Maintenance | M32: ='Monthly Expenses Budget'!C31 -> 230 | P32: 26 | Q32: =Q31+30 -> 46841 | R32: =TEXT($Q32,"MMMM")&TEXT($Q32," YYYY") -> March 2028 | S32: =($V$1/12+1)*S31+T31 -> 11135759 | U32: =($V$2/12+1)*U31+$V$3 -> 1413711.3 | V32: =V31+$I$56 -> 547452.02 | W32: =W31+X31 -> 7524000 | X32: =T32 -> 0 | Y32: =SUM(S32:V32)-W32 -> 5572922.7
L33: ='Monthly Expenses Budget'!B39 -> Health | M33: ='Monthly Expenses Budget'!C39 -> 1514.7033 | P33: 27 | Q33: =Q32+30 -> 46871 | R33: =TEXT($Q33,"MMMM")&TEXT($Q33," YYYY") -> April 2028 | S33: =($V$1/12+1)*S32+T32 -> 11200718 | U33: =($V$2/12+1)*U32+$V$3 -> 1435492.2 | V33: =V32+$I$56 -> 565110.1 | W33: =W32+X32 -> 7524000 | X33: =T33 -> 0 | Y33: =SUM(S33:V33)-W33 -> 5677320.3
B34: Savings Account 1 | E34: =M40 -> 106000 | G34: Credit Card 1 (total limit) | I34: 10000 | L34: ='Monthly Expenses Budget'!B49 -> Discretionary | M34: ='Monthly Expenses Budget'!C49 -> 1100 | P34: 28 | Q34: =Q33+30 -> 46901 | R34: =TEXT($Q34,"MMMM")&TEXT($Q34," YYYY") -> May 2028 | S34: =($V$1/12+1)*S33+T33 -> 11266056 | U34: =($V$2/12+1)*U33+$V$3 -> 1457454.7 | V34: =V33+$I$56 -> 582768.18 | W34: =W33+X33 -> 7524000 | X34: =T34 -> 0 | Y34: =SUM(S34:V34)-W34 -> 5782278.4
B35: Savings Account 2 | E35: =M41 -> 0 | G35: Credit Card 2 (total limit) | I35: 2000 | L35: ='Monthly Expenses Budget'!B58 -> Sports / Activities | M35: ='Monthly Expenses Budget'!C58 -> 397.5 | P35: 29 | Q35: =Q34+30 -> 46931 | R35: =TEXT($Q35,"MMMM")&TEXT($Q35," YYYY") -> June 2028 | S35: =($V$1/12+1)*S34+T34 -> 11331774 | U35: =($V$2/12+1)*U34+$V$3 -> 1479600.1 | V35: =V34+$I$56 -> 600426.26 | W35: =W34+X34 -> 7524000 | X35: =T35 -> 0 | Y35: =SUM(S35:V35)-W35 -> 5887800.6
G36: Personal Loans | L36: ='Monthly Expenses Budget'!B64 -> Other | M36: ='Monthly Expenses Budget'!C64 -> 1100 | P36: 30 | Q36: =Q35+30 -> 46961 | R36: =TEXT($Q36,"MMMM")&TEXT($Q36," YYYY") -> July 2028 | S36: =($V$1/12+1)*S35+T35 -> 11397876 | U36: =($V$2/12+1)*U35+$V$3 -> 1501930.1 | V36: =V35+$I$56 -> 618084.34 | W36: =W35+X35 -> 7524000 | X36: =T36 -> 0 | Y36: =SUM(S36:V36)-W36 -> 5993890.7
B37: Stocks (local) | E37: =M43 -> 190000 | G37: Other Loans | P37: 31 | Q37: =Q36+30 -> 46991 | R37: =TEXT($Q37,"MMMM")&TEXT($Q37," YYYY") -> August 2028 | S37: =($V$1/12+1)*S36+T36 -> 11464364 | U37: =($V$2/12+1)*U36+$V$3 -> 1524446.2 | V37: =V36+$I$56 -> 635742.42 | W37: =W36+X36 -> 7524000 | X37: =T37 -> 0 | Y37: =SUM(S37:V37)-W37 -> 6100552.4
B38: Stocks (offshore) | E38: =M44 -> 218000 | P38: 32 | Q38: =Q37+30 -> 47021 | R38: =TEXT($Q38,"MMMM")&TEXT($Q38," YYYY") -> September 2028 | S38: =($V$1/12+1)*S37+T37 -> 11531239 | U38: =($V$2/12+1)*U37+$V$3 -> 1547149.9 | V38: =V37+$I$56 -> 653400.51 | W38: =W37+X37 -> 7524000 | X38: =T38 -> 0 | Y38: =SUM(S38:V38)-W38 -> 6207789.7
B39: Other stocks | E39: =M45 -> 516000 | L39: ASSETS | P39: 33 | Q39: =Q38+30 -> 47051 | R39: =TEXT($Q39,"MMMM")&TEXT($Q39," YYYY") -> October 2028 | S39: =($V$1/12+1)*S38+T38 -> 11598505 | U39: =($V$2/12+1)*U38+$V$3 -> 1570042.9 | V39: =V38+$I$56 -> 671058.59 | W39: =W38+X38 -> 7524000 | X39: =T39 -> 0 | Y39: =SUM(S39:V39)-W39 -> 6315606.3
L40: Savings (account 1) | M40: 106000 | P40: 34 | Q40: =Q39+30 -> 47081 | R40: =TEXT($Q40,"MMMM")&TEXT($Q40," YYYY") -> November 2028 | S40: =($V$1/12+1)*S39+T39 -> 11666163 | T40: =$V$4 -> 3000000 | U40: =($V$2/12+1)*U39+$V$3 -> 1593126.6 | V40: =V39+$I$56 -> 688716.67 | W40: =W39+X39 -> 7524000 | X40: =T40 -> 3000000 | Y40: =SUM(S40:V40)-W40 -> 9424006
...

Sheet FV_July25 
U1: Property Growth Rate (PY) | V1: 0.07
B2: INCOME STATEMENT | L2: INPUTS!!! Fill out the ORANGE cells ONLY | U2: Stock Growth Rate (PY) | V2: 0.1
U3: Stock contribution per month | V3: 10000 | AI3: NET GROWTH FORECAST
B4: INCOME | C4: PER YEAR | D4: PER MONTH | E4: CASHFLOW PM | G4: PASSIVE | H4: PER MONTH | I4: PER YEAR | L4: INCOME | U4: Yearly Prop Purchase Value | V4: 2000000
G5: PASSIVE INCOME | H5: =SUM(D8:D18) -> 9953 | I5: =H5*12 -> 119436
B6: Salary 1 | C6: =D6*12 -> 276000 | D6: =M6 -> 23000 | L6: Salary 1 (ex tax per month) | M6: 23000 | P6: Date | Q6: Date | R6: Month | S6: Properties | T6: Add Prop | U6: Stocks | V6: Savings | W6: Liabilities | X6: Add Liab | Y6: Total Net Worth
B7: Salary 2 | C7: =D7*12 -> 0 | D7: =M7 -> 0 | L7: Salary 2 (ex tax per month) | P7: 1 | Q7: =TODAY() -> 46091 | R7: =TEXT($Q7,"MMMM")&TEXT($Q7," YYYY") -> March 2026 | S7: =SUM(E48:E54) -> 4205000 | U7: =SUM(E41:E43) -> 1044000 | V7: =$E$38 -> 6000 | W7: =$I$57 -> 1480000 | X7: =T7 -> 0 | Y7: =SUM(S7:V7)-W7 -> 3775000
B8: Interest Earned (from savings) | D8: =M8 -> 10 | E8: =D8 -> 10 | L8: Interest from Savings (per month) | M8: 10 | P8: 2 | Q8: =Q7+30 -> 46121 | R8: =TEXT($Q8,"MMMM")&TEXT($Q8," YYYY") -> April 2026 | S8: =($V$1/12+1)*S7+T7 -> 4229529.2 | U8: =($V$2/12+1)*U7+$V$3 -> 1062700 | V8: =V7+$I$65 -> 22020.498 | W8: =W7+X7 -> 1480000 | X8: =T8 -> 0 | Y8: =SUM(S8:V8)-W8 -> 3834249.7
B9: Dividends | C9: =D9*12 -> 9960 | D9: =M9 -> 830 | E9: =D9 -> 830 | L9: Income from Dividends (per month) | M9: 830 | P9: 3 | Q9: =Q8+30 -> 46151 | R9: =TEXT($Q9,"MMMM")&TEXT($Q9," YYYY") -> May 2026 | S9: =($V$1/12+1)*S8+T8 -> 4254201.4 | U9: =($V$2/12+1)*U8+$V$3 -> 1081555.8 | V9: =V8+$I$65 -> 38040.995 | W9: =W8+X8 -> 1480000 | X9: =T9 -> 0 | Y9: =SUM(S9:V9)-W9 -> 3893798.2
B10: Other income | D10: =M10 -> 0 | L10: Any other income (per month) | M10: 0 | P10: 4 | Q10: =Q9+30 -> 46181 | R10: =TEXT($Q10,"MMMM")&TEXT($Q10," YYYY") -> June 2026 | S10: =($V$1/12+1)*S9+T9 -> 4279017.6 | U10: =($V$2/12+1)*U9+$V$3 -> 1100568.8 | V10: =V9+$I$65 -> 54061.493 | W10: =W9+X9 -> 1480000 | X10: =T10 -> 0 | Y10: =SUM(S10:V10)-W10 -> 3953647.9
P11: 5 | Q11: =Q10+30 -> 46211 | R11: =TEXT($Q11,"MMMM")&TEXT($Q11," YYYY") -> July 2026 | S11: =($V$1/12+1)*S10+T10 -> 4303978.5 | U11: =($V$2/12+1)*U10+$V$3 -> 1119740.2 | V11: =V10+$I$65 -> 70081.99 | W11: =W10+X10 -> 1480000 | X11: =T11 -> 0 | Y11: =SUM(S11:V11)-W11 -> 4013800.7
B12: Real Estate / Other income (gross): | G12: Property Yield | H12: % Gross | I12: % Net | P12: 6 | Q12: =Q11+30 -> 46241 | R12: =TEXT($Q12,"MMMM")&TEXT($Q12," YYYY") -> August 2026 | S12: =($V$1/12+1)*S11+T11 -> 4329085.1 | U12: =($V$2/12+1)*U11+$V$3 -> 1139071.4 | V12: =V11+$I$65 -> 86102.488 | W12: =W11+X11 -> 1480000 | X12: =T12 -> 0 | Y12: =SUM(S12:V12)-W12 -> 4074258.9
P13: 7 | Q13: =Q12+30 -> 46271 | R13: =TEXT($Q13,"MMMM")&TEXT($Q13," YYYY") -> September 2026 | S13: =($V$1/12+1)*S12+T12 -> 4354338.1 | U13: =($V$2/12+1)*U12+$V$3 -> 1158563.6 | V13: =V12+$I$65 -> 102122.99 | W13: =W12+X12 -> 1480000 | X13: =T13 -> 0 | Y13: =SUM(S13:V13)-W13 -> 4135024.7
